<robot name="BUD-E">
<!--    <macro name="smart_arm" params="parent *origin">	-->
<!--
	<link name="base_link">
		<visual>
			<geometry>
				<cylinder length="0.1" radius="0.1"/>
			</geometry>
			<origin xyz="0 0 0" rpy="0 0 0"/>
			<material name="black">
				<color rgba="0 0 0 1"/>
			</material>
		</visual>
	</link>
-->
	<link name="base">
		<visual>
			<origin xyz="0 0 0.02" rpy="0 0 0" />
			<geometry>
				<box size="0.115 0.115 0.04" />
			</geometry>
			<material name="red">
				<color rgba="1 1 0 1" />
			</material>
		</visual>
	</link>

        <link name="arm_base_link">
            <inertial>
                <mass value="0.125" />
                <origin xyz="0 0 0.00893364" rpy="0 0 0" />
                <inertia ixx="1.0" ixy="0.0" ixz="0.0"
                         iyy="1.0" iyz="0.0" 
                         izz="1.0" />
            </inertial>
            
            	<visual>
                	<origin xyz="0.0 0.0 0.0" rpy="0 0 0" />
                	<geometry>
                    	<mesh filename="package://smart_arm_description/meshes/collada/arm_base.dae"/>
                	</geometry>
                	<material name="Green" />
            	</visual>

<!--
            
            <collision>
                <origin xyz="0.0 0.0 0.0" rpy="0 0 0" />
                <geometry>
                    <mesh filename="package://smart_arm_description/meshes/collada/arm_base.dae"/>
                </geometry>
            </collision>
-->

        </link>
        
        <link name="arm_shoulder_pan_link">
            <inertial>
                <mass value="0.405" />
                <origin xyz="0.02988871 0 0.02056699" rpy="0 0 0" />
                <inertia ixx="1.0" ixy="0.0" ixz="0.0"
                         iyy="1.0" iyz="0.0" 
                         izz="1.0" />
            </inertial>
            
            <visual>
                <origin xyz="0.0 0.0 0.005" rpy="0 0 0" />
                	<geometry>
                    	<mesh filename="package://smart_arm_description/meshes/collada/arm_shoulder_pan.dae"/>
                	</geometry>
                <material name="Grey" />
            </visual>

<!--
            
            <collision>
                <origin xyz="0.0 0.0 0.0" rpy="0 0 0" />
                <geometry>
                    <mesh filename="package://smart_arm_description/meshes/collada/arm_shoulder_pan.dae"/>
                </geometry>
            </collision>

-->

        </link>
        
        <link name="arm_shoulder_pitch_link">
            <inertial>
                <mass value="0.18" />
                <origin xyz="0.13999458 0 0.00064711" rpy="0 0 0" />
                <inertia ixx="1.0" ixy="0.0" ixz="0.0"
                         iyy="1.0" iyz="0.0" 
                         izz="1.0" />
            </inertial>
            
            <visual>
                <origin xyz="0.0 0.0 0.0" rpy="0 0 0" />
                	<geometry>
                    	<mesh filename="package://smart_arm_description/meshes/collada/arm_shoulder_pitch.dae"/>
                	</geometry>
                <material name="Blue" />
            </visual>
   
<!--
         
            <collision>
                <origin xyz="0.0 0.0 0.0" rpy="0 0 0" />
                <geometry>
                    <mesh filename="package://smart_arm_description/meshes/collada/arm_shoulder_pitch.dae"/>
                </geometry>
            </collision>
-->

        </link>
        
        <link name="arm_elbow_flex_link">
            <inertial>
                <mass value="0.12" />
                <origin xyz="0.04463361 0 0.00720194" rpy="0 0 0" />
                <inertia ixx="1.0" ixy="0.0" ixz="0.0"
                         iyy="1.0" iyz="0.0" 
                         izz="1.0" />
            </inertial>
            
            <visual>
                <origin xyz="0.0 0.0 0.0" rpy="0 0 0" />
                	<geometry>
                    	<mesh filename="package://smart_arm_description/meshes/collada/arm_elbow_flex.dae"/>
                	</geometry>
                <material name="Green" />
            </visual>

<!--
            
            <collision>
                <origin xyz="0.0 0.0 0.0" rpy="0 0 0" />
                <geometry>
                    <mesh filename="package://smart_arm_description/meshes/collada/arm_elbow_flex.dae"/>
                </geometry>
            </collision>
-->


        </link>
        
        <link name="arm_wrist_roll_link">
            <inertial>
                <mass value="0.13" />
                <origin xyz="0.02539960 0 0" rpy="0 0 0" />
                <inertia ixx="1.0" ixy="0.0" ixz="0.0"
                         iyy="1.0" iyz="0.0" 
                         izz="1.0" />
            </inertial>
            
            <visual>
                <origin xyz="0.0 0.0 0.0" rpy="0 0 0" />
                	<geometry>
                    	<mesh filename="package://smart_arm_description/meshes/collada/arm_wrist_roll.dae"/>
                	</geometry>
                <material name="Grey" />
            </visual>

<!--
            
            <collision>
                <origin xyz="0.0 0.0 0.0" rpy="0 0 0" />
                <geometry>
                    <mesh filename="package://smart_arm_description/meshes/collada/arm_wrist_roll.dae"/>
                </geometry>
            </collision>
-->

        </link>
        
        <link name="arm_right_finger_link">
            <inertial>
                <mass value="0.0225" />
                <origin xyz="0.03058625 -0.01804371 -0.00941599" rpy="0 0 0" />
                <inertia ixx="1.0" ixy="0.0" ixz="0.0"
                         iyy="1.0" iyz="0.0" 
                         izz="1.0" />
            </inertial>
            
            <visual>
                <origin xyz="0.0 0.0 0.0" rpy="0 0 0" />
                	<geometry>
                    	<mesh filename="package://smart_arm_description/meshes/collada/arm_right_finger.dae"/>
                	</geometry>
                <material name="Blue" />
            </visual>

<!--
            
            <collision>
                <origin xyz="0.0 0.0 0.0" rpy="0 0 0" />
                <geometry>
                    <mesh filename="package://smart_arm_description/meshes/collada/arm_right_finger.dae"/>
                </geometry>
            </collision>
-->

        </link>
        
        <link name="arm_left_finger_link">
            <inertial>
                <mass value="0.0225" />
                <origin xyz="0.03058625 0.01804371 -0.00941599" rpy="0 0 0" />
                <inertia ixx="1.0" ixy="0.0" ixz="0.0"
                         iyy="1.0" iyz="0.0" 
                         izz="1.0" />
            </inertial>
            
            <visual>
                <origin xyz="0.0 0.0 0.0" rpy="0 0 0" />
                	<geometry>
                    	<mesh filename="package://smart_arm_description/meshes/collada/arm_left_finger.dae"/>
                	</geometry>
                <material name="Green" />
            </visual>

<!--
            
            <collision>
                <origin xyz="0.0 0.0 0.0" rpy="0 0 0" />
                <geometry>
                    <mesh filename="package://smart_arm_description/meshes/collada/arm_left_finger.dae"/>
                </geometry>
            </collision>
-->

        </link>
	

        <!-- ****** JOINT DEFINITIONS ****** -->
        
        <!-- Arm's base joint -->
        <joint name="arm_base_joint" type="fixed">
            <origin xyz="-0 0 0" rpy="0 0 0" /> 
            <parent link="base"/>
            <child link="arm_base_link"/>
        </joint>
        
        <!-- Shoulder pan joint -->
        <joint name="shoulder_pan_joint" type="revolute" >
            <origin xyz="-0.0075 0 0.025" rpy="0 0 0" />
            <parent link="arm_base_link" />
            <child link="arm_shoulder_pan_link"/>
            
            <axis xyz="0 0 1"/>
            <limit  lower="-1.22" upper="1.22" effort="300" velocity="1.17" />
<!--            <safety_controller k_position="100" k_velocity="15.0" soft_lower_limit="${-1.229876+0.1}" soft_upper_limit="${1.229876-0.1}" />		-->
            <dynamics damping="50" friction="1"/>
        </joint>
        
        <!-- Shoulder tilt joint -->
        <joint name="shoulder_pitch_joint" type="revolute">
            <origin xyz="0.07 0 0.0445" rpy="0 0 0" />
            <parent link="arm_shoulder_pan_link"/>
            <child link="arm_shoulder_pitch_link" />
            
            <axis xyz="0 -1 0"/>
            <limit  lower="-1.04719755" upper="1.972222" effort="300" velocity="1.17" />
<!--            <safety_controller k_position="100" k_velocity="15.0" soft_lower_limit="${-1.04719755+0.1}" soft_upper_limit="${1.972222-0.1}" />  -->
            <dynamics damping="50" friction="1"/>
        </joint>
        
        <!-- Elbow tilt joint -->
        <joint name="elbow_flex_joint" type="revolute">
            <origin xyz="0.1815 0 0" rpy="0 0 0" />
            <parent link="arm_shoulder_pitch_link"/>
            <child link="arm_elbow_flex_link" />
            
            <axis xyz="0 -1 0"/>
            <!-- From -113 to 108 degrees -->
            <limit  lower="-1.972222" upper="1.8849556" effort="300" velocity="1.17" />
            <dynamics damping="50" friction="1"/>
<!--            <safety_controller k_position="100" k_velocity="15.0" soft_lower_limit="${-1.972222+0.1}" soft_upper_limit="${1.8849556-0.1}" /> -->
        </joint>
        
        <!-- Wrist rotate joint -->
        <joint name="wrist_roll_joint" type="revolute">
            <origin xyz="0.07 0 0.023" rpy="0 0 0" />
            <parent link="arm_elbow_flex_link"/>
            <child link="arm_wrist_roll_link" />
            
            <axis xyz="-1 0 0"/>
            <!-- From -150 to 150 degrees -->
            <limit  lower="-2.6179939" upper="2.6179939" effort="300" velocity="1.17" />
            <dynamics damping="50" friction="1"/>
<!--            <safety_controller k_position="100" k_velocity="15.0" soft_lower_limit="${-2.6179939+0.1}" soft_upper_limit="${2.6179939-0.1}" />  -->
        </joint>
        
        <!-- Gripper right finger joint -->
        <joint name="right_finger_joint" type="revolute">
            <origin xyz="0.0415 -0.0175 0" rpy="0 0 0" />
            <parent link="arm_wrist_roll_link"/>
            <child link="arm_right_finger_link" />
            
            <axis xyz="0 0 1"/>
            <!-- From 14 to -45 degrees -->
            <limit  lower="-0.838576116" upper="0.245436912" effort="300" velocity="1.17" />
            <dynamics damping="50" friction="1"/>
<!--            <safety_controller k_position="100" k_velocity="15.0" soft_lower_limit="${-0.838576116+0.1}" soft_upper_limit="${0.245436912-0.1}" />  -->
        </joint>
        
        <!-- Gripper left finger joint -->
        <joint name="left_finger_joint" type="revolute">
            <origin xyz="0.0415 0.0175 0" rpy="0 0 0" />
            <parent link="arm_wrist_roll_link"/>
            <child link="arm_left_finger_link" />
            
            <axis xyz="0 0 1"/>
            <!-- From -14 to 45 degrees -->
            <limit  lower="-0.240323643" upper="0.843689385" effort="300" velocity="1.17" />
            <dynamics damping="50" friction="1"/>
<!--            <safety_controller k_position="100" k_velocity="15.0" soft_lower_limit="${-0.240323643+0.1}" soft_upper_limit="${0.843689385-0.1}" /> -->
        </joint>
        
<!--    </macro> -->
</robot>


